[20/02/2018 14:15] ERROR red load_cogs 573: You need to run `pip3 install youtube_dl`
Traceback (most recent call last):
  File "red.py", line 570, in load_cogs
    owner_cog._load_cog(extension)
  File "C:\Users\ImJustJeff\Documents\Discord\bot\Red-DiscordBot\cogs\owner.py", line 948, in _load_cog
    self.bot.load_extension(mod_obj.__name__)
  File "C:\Users\ImJustJeff\AppData\Local\Programs\Python\Python36-32\lib\site-packages\discord\ext\commands\bot.py", line 738, in load_extension
    lib.setup(self)
  File "C:\Users\ImJustJeff\Documents\Discord\bot\Red-DiscordBot\cogs\audio.py", line 2351, in setup
    raise RuntimeError("You need to run `pip3 install youtube_dl`")
RuntimeError: You need to run `pip3 install youtube_dl`
[20/02/2018 14:15] ERROR red load_cogs 573: You need the imgurpython module to use this.
pip3 install imgurpython
Traceback (most recent call last):
  File "red.py", line 570, in load_cogs
    owner_cog._load_cog(extension)
  File "C:\Users\ImJustJeff\Documents\Discord\bot\Red-DiscordBot\cogs\owner.py", line 948, in _load_cog
    self.bot.load_extension(mod_obj.__name__)
  File "C:\Users\ImJustJeff\AppData\Local\Programs\Python\Python36-32\lib\site-packages\discord\ext\commands\bot.py", line 738, in load_extension
    lib.setup(self)
  File "C:\Users\ImJustJeff\Documents\Discord\bot\Red-DiscordBot\cogs\image.py", line 165, in setup
    raise RuntimeError("You need the imgurpython module to use this.\n"
RuntimeError: You need the imgurpython module to use this.
pip3 install imgurpython
[23/02/2018 17:48] ERROR owner load 74: You need to run `pip3 install youtube_dl`
Traceback (most recent call last):
  File "C:\Users\ImJustJeff\Documents\Discord\bot\Red-DiscordBot\cogs\owner.py", line 65, in load
    self._load_cog(module)
  File "C:\Users\ImJustJeff\Documents\Discord\bot\Red-DiscordBot\cogs\owner.py", line 948, in _load_cog
    self.bot.load_extension(mod_obj.__name__)
  File "C:\Users\ImJustJeff\AppData\Local\Programs\Python\Python36-32\lib\site-packages\discord\ext\commands\bot.py", line 738, in load_extension
    lib.setup(self)
  File "C:\Users\ImJustJeff\Documents\Discord\bot\Red-DiscordBot\cogs\audio.py", line 2351, in setup
    raise RuntimeError("You need to run `pip3 install youtube_dl`")
RuntimeError: You need to run `pip3 install youtube_dl`
[09/03/2018 14:01] ERROR red <module> 634: Fatal exception, attempting graceful logout
Traceback (most recent call last):
  File "lib\aiohttp\connector.py", line 601, in _create_direct_connection
    local_addr=self._local_addr)
  File "C:\Users\ImJustJeff\AppData\Local\Programs\Python\Python36-32\lib\asyncio\base_events.py", line 777, in create_connection
    raise exceptions[0]
  File "C:\Users\ImJustJeff\AppData\Local\Programs\Python\Python36-32\lib\asyncio\base_events.py", line 764, in create_connection
    yield from self.sock_connect(sock, address)
  File "C:\Users\ImJustJeff\AppData\Local\Programs\Python\Python36-32\lib\asyncio\selector_events.py", line 450, in sock_connect
    return (yield from fut)
  File "C:\Users\ImJustJeff\AppData\Local\Programs\Python\Python36-32\lib\asyncio\selector_events.py", line 480, in _sock_connect_cb
    raise OSError(err, 'Connect call failed %s' % (address,))
TimeoutError: [Errno 10060] Connect call failed ('104.16.58.5', 443)

The above exception was the direct cause of the following exception:

Traceback (most recent call last):
  File "lib\aiohttp\connector.py", line 304, in connect
    yield from self._create_connection(req)
  File "lib\aiohttp\connector.py", line 578, in _create_connection
    transport, proto = yield from self._create_direct_connection(req)
  File "lib\aiohttp\connector.py", line 624, in _create_direct_connection
    (req.host, req.port, exc.strerror)) from exc
aiohttp.errors.ClientOSError: [Errno 10060] Can not connect to discordapp.com:443 [Connect call failed ('104.16.58.5', 443)]

The above exception was the direct cause of the following exception:

Traceback (most recent call last):
  File "red.py", line 614, in <module>
    loop.run_until_complete(main(bot))
  File "C:\Users\ImJustJeff\AppData\Local\Programs\Python\Python36-32\lib\asyncio\base_events.py", line 467, in run_until_complete
    return future.result()
  File "red.py", line 603, in main
    yield from bot.connect()
  File "lib\discord\client.py", line 451, in connect
    self.ws = yield from DiscordWebSocket.from_client(self, resume=True)
  File "lib\discord\gateway.py", line 198, in from_client
    gateway = yield from client.http.get_gateway()
  File "lib\discord\http.py", line 633, in get_gateway
    data = yield from self.request(Route('GET', '/gateway'))
  File "lib\discord\http.py", line 137, in request
    r = yield from self.session.request(method, url, **kwargs)
  File "lib\aiohttp\client.py", line 555, in __iter__
    resp = yield from self._coro
  File "lib\aiohttp\client.py", line 198, in _request
    conn = yield from self._connector.connect(req)
  File "lib\aiohttp\connector.py", line 314, in connect
    .format(key, exc.strerror)) from exc
aiohttp.errors.ClientOSError: [Errno 10060] Cannot connect to host discordapp.com:443 ssl:True [Can not connect to discordapp.com:443 [Connect call failed ('104.16.58.5', 443)]]
[15/03/2018 16:17] ERROR owner avatar 494: Unsupported image type given
Traceback (most recent call last):
  File "C:\Users\ImJustJeff\Documents\Discord\bot\Red-DiscordBot\cogs\owner.py", line 488, in avatar
    await self.bot.edit_profile(self.bot.settings.password, avatar=data)
  File "lib\discord\client.py", line 1840, in edit_profile
    avatar = utils._bytes_to_base64_data(avatar_bytes)
  File "lib\discord\utils.py", line 247, in _bytes_to_base64_data
    mime = _get_mime_type_for_image(data)
  File "lib\discord\utils.py", line 243, in _get_mime_type_for_image
    raise InvalidArgument('Unsupported image type given')
discord.errors.InvalidArgument: Unsupported image type given
[15/03/2018 16:24] ERROR owner avatar 494: Unsupported image type given
Traceback (most recent call last):
  File "C:\Users\ImJustJeff\Documents\Discord\bot\Red-DiscordBot\cogs\owner.py", line 488, in avatar
    await self.bot.edit_profile(self.bot.settings.password, avatar=data)
  File "lib\discord\client.py", line 1840, in edit_profile
    avatar = utils._bytes_to_base64_data(avatar_bytes)
  File "lib\discord\utils.py", line 247, in _bytes_to_base64_data
    mime = _get_mime_type_for_image(data)
  File "lib\discord\utils.py", line 243, in _get_mime_type_for_image
    raise InvalidArgument('Unsupported image type given')
discord.errors.InvalidArgument: Unsupported image type given
[15/03/2018 16:25] ERROR owner avatar 494: Host could not be detected.
Traceback (most recent call last):
  File "C:\Users\ImJustJeff\Documents\Discord\bot\Red-DiscordBot\cogs\owner.py", line 486, in avatar
    async with self.session.get(url) as r:
  File "lib\aiohttp\client.py", line 565, in __aenter__
    self._resp = yield from self._coro
  File "lib\aiohttp\client.py", line 195, in _request
    proxy=proxy, proxy_auth=proxy_auth, timeout=timeout)
  File "lib\aiohttp\client_reqrep.py", line 91, in __init__
    self.update_host(url)
  File "lib\aiohttp\client_reqrep.py", line 111, in update_host
    raise ValueError('Host could not be detected.')
ValueError: Host could not be detected.
[25/03/2018 19:48] ERROR red on_command_error 369: Exception in command 'userinfo'
Traceback (most recent call last):
  File "lib\discord\ext\commands\core.py", line 50, in wrapped
    ret = yield from coro(*args, **kwargs)
  File "C:\Users\ImJustJeff\Documents\Discord\bot\Red-DiscordBot\cogs\general.py", line 210, in userinfo
    roles = sorted(roles, key=[x.name for x in server.role_hierarchy
ValueError: "caike's mad caike invention" is not in list
[25/03/2018 19:48] ERROR red on_command_error 369: Exception in command 'userinfo'
Traceback (most recent call last):
  File "lib\discord\ext\commands\core.py", line 50, in wrapped
    ret = yield from coro(*args, **kwargs)
  File "C:\Users\ImJustJeff\Documents\Discord\bot\Red-DiscordBot\cogs\general.py", line 210, in userinfo
    roles = sorted(roles, key=[x.name for x in server.role_hierarchy
ValueError: "caike's mad caike invention" is not in list
[12/04/2018 16:25] ERROR red load_cogs 573: ('invalid syntax', ('C:\\Users\\ImJustJeff\\Documents\\Discord\\bot\\Red-DiscordBot\\cogs\\general.py', 182, 12, '        elif msg = "Kisses you <3 https://imgur.com/GFwg6AA" + name\n'))
Traceback (most recent call last):
  File "C:\Users\ImJustJeff\Documents\Discord\bot\Red-DiscordBot\cogs\owner.py", line 946, in _load_cog
    mod_obj = importlib.import_module(cogname)
  File "C:\Users\ImJustJeff\AppData\Local\Programs\Python\Python36-32\lib\importlib\__init__.py", line 126, in import_module
    return _bootstrap._gcd_import(name[level:], package, level)
  File "<frozen importlib._bootstrap>", line 994, in _gcd_import
  File "<frozen importlib._bootstrap>", line 971, in _find_and_load
  File "<frozen importlib._bootstrap>", line 955, in _find_and_load_unlocked
  File "<frozen importlib._bootstrap>", line 665, in _load_unlocked
  File "<frozen importlib._bootstrap_external>", line 674, in exec_module
  File "<frozen importlib._bootstrap_external>", line 781, in get_code
  File "<frozen importlib._bootstrap_external>", line 741, in source_to_code
  File "<frozen importlib._bootstrap>", line 219, in _call_with_frames_removed
  File "C:\Users\ImJustJeff\Documents\Discord\bot\Red-DiscordBot\cogs\general.py", line 182
    elif msg = "Kisses you <3 https://imgur.com/GFwg6AA" + name
       ^
SyntaxError: invalid syntax

During handling of the above exception, another exception occurred:

Traceback (most recent call last):
  File "red.py", line 570, in load_cogs
    owner_cog._load_cog(extension)
  File "C:\Users\ImJustJeff\Documents\Discord\bot\Red-DiscordBot\cogs\owner.py", line 950, in _load_cog
    raise CogLoadError(*e.args)
cogs.owner.CogLoadError: ('invalid syntax', ('C:\\Users\\ImJustJeff\\Documents\\Discord\\bot\\Red-DiscordBot\\cogs\\general.py', 182, 12, '        elif msg = "Kisses you <3 https://imgur.com/GFwg6AA" + name\n'))
